Workbook

Sheet ALG Caseware
A1: WP Index ID | B1: Process Flow | C1: Process Flow-2 | D1: Type | E1: FS Section | F1: Document Name | G1: Source | H1: File Format | I1: PPC Form Reference | J1: Notes | L1: Time Bucket | M1: Rationale | N1: Audit Manager Override | O1: Audit Reviewer Note
A2: FS-FINAL | D2: FS Section | E2: Financial Statements and Deliverables Section | F2: Final PDF Copy of the Audited Financial Statements | G2: =_xlfn.XLOOKUP(F2,'NPO Caseware'!G:G,'NPO Caseware'!H:H) -> HCLLP WP | H2: =_xlfn.XLOOKUP(F2,'NPO Caseware'!G:G,'NPO Caseware'!I:I) -> PDF | L2: time_static | M2: FS draft/final — FS layout stable
A3: FS-CV | D3: FS Section | E3: Financial Statements and Deliverables Section | F3: Working Copy of the CaseView Financial Statements | G3: =_xlfn.XLOOKUP(F3,'NPO Caseware'!G:G,'NPO Caseware'!H:H) -> HCLLP WP | H3: =_xlfn.XLOOKUP(F3,'NPO Caseware'!G:G,'NPO Caseware'!I:I) -> PDF | L3: time_static | M3: CaseView FS working copy — layout stable
A4: FS-CV-1 | D4: FS Section | E4: Financial Statements and Deliverables Section | F4: Cash Flow Worksheet (if applicable) | G4: =_xlfn.XLOOKUP(F4,'NPO Caseware'!G:G,'NPO Caseware'!H:H) -> HCLLP WP | H4: =_xlfn.XLOOKUP(F4,'NPO Caseware'!G:G,'NPO Caseware'!I:I) -> Excel | L4: time_static | M4: cash flow worksheet — format stable
A5: FS-PROG | D5: FS Section | E5: Financial Statements and Deliverables Section | F5: Audit Program for General Auditing and Completion Procedures | G5: =_xlfn.XLOOKUP(F5,'NPO Caseware'!G:G,'NPO Caseware'!H:H) -> PPC | H5: =_xlfn.XLOOKUP(F5,'NPO Caseware'!G:G,'NPO Caseware'!I:I) -> Word | I5: ALG-AP-20 | L5: time_static | M5: audit program — standard procedure
A6: FS-PROG-1 | D6: FS Section | E6: Financial Statements and Deliverables Section | F6: Additional General Auditing and Completion Procedures for an Initial Audit (If applicable) | G6: PPC | H6: Word | I6: ALG-IA-20 | J6: Use only if this is a first year audit for Harshwal & CO/Blue Arrow CPAs | L6: time_static | M6: FS deliverables — default standard procedure (section default)
A7: FS-1 | D7: FS Section | E7: Financial Statements and Deliverables Section | F7: Governmental Disclosure Checklist | G7: PPC | H7: Word | I7: ALG-CX-13.1 | L7: time_static | M7: disclosure checklist — slowly evolving
A8: FS-2 | D8: FS Section | E8: Financial Statements and Deliverables Section | F8: Management Representation Letter (Client Endorsed) | G8: =_xlfn.XLOOKUP(F8,'NPO Caseware'!G:G,'NPO Caseware'!H:H) -> PBC | H8: =_xlfn.XLOOKUP(F8,'NPO Caseware'!G:G,'NPO Caseware'!I:I) -> PDF | L8: time_static | M8: MRL template — standard
A9: FS-2-1 | D9: FS Section | E9: Financial Statements and Deliverables Section | F9: Management Representation Letter Template | G9: =_xlfn.XLOOKUP(F9,'NPO Caseware'!G:G,'NPO Caseware'!H:H) -> PPC | H9: =_xlfn.XLOOKUP(F9,'NPO Caseware'!G:G,'NPO Caseware'!I:I) -> Word | I9: ALG-CL-3.1 | L9: time_static | M9: MRL template — standard
A10: FS-3 | D10: FS Section | E10: Financial Statements and Deliverables Section | F10: Legal Representation Letter (Returned Response from Attorney) | G10: =_xlfn.XLOOKUP(F10,'NPO Caseware'!G:G,'NPO Caseware'!H:H) -> HCLLP WP | H10: =_xlfn.XLOOKUP(F10,'NPO Caseware'!G:G,'NPO Caseware'!I:I) -> PDF | L10: time_static | M10: FS deliverables — default standard procedure (section default)
A11: FS-4 | D11: FS Section | E11: Financial Statements and Deliverables Section | F11: Communication to Those Charged with Governance at Conclusion (Final PDF Copy provided to Client) | G11: =_xlfn.XLOOKUP(F11,'NPO Caseware'!G:G,'NPO Caseware'!H:H) -> HCLLP WP | H11: =_xlfn.XLOOKUP(F11,'NPO Caseware'!G:G,'NPO Caseware'!I:I) -> PDF | L11: time_static | M11: FS draft/final — FS layout stable
A12: FS-4-1 | D12: FS Section | E12: Financial Statements and Deliverables Section | F12: Communication to Those Charged with Governance at Conclusion Template | G12: =_xlfn.XLOOKUP(F12,'NPO Caseware'!G:G,'NPO Caseware'!H:H) -> PPC | H12: =_xlfn.XLOOKUP(F12,'NPO Caseware'!G:G,'NPO Caseware'!I:I) -> Word | I12: ALG-CL-5.2 | L12: time_static | M12: TCWG comm — standard
A13: FS-5 | D13: FS Section | E13: Financial Statements and Deliverables Section | F13: Audit Presentation PowerPoint | G13: =_xlfn.XLOOKUP(F13,'NPO Caseware'!G:G,'NPO Caseware'!H:H) -> HCLLP WP | H13: =_xlfn.XLOOKUP(F13,'NPO Caseware'!G:G,'NPO Caseware'!I:I) -> PPT | L13: time_static | M13: FS deliverables — default standard procedure (section default)
A14: FS-6 | D14: FS Section | E14: Financial Statements and Deliverables Section | F14: Final Analytical Procedures - Opinion Unit #1 | G14: HCLLP WP | H14: Excel | L14: time_static | M14: substantive procedure — standard
A15: FS-6-1 | D15: FS Section | E15: Financial Statements and Deliverables Section | F15: Final Analytical Procedures - Opinion Unit #2 | G15: HCLLP WP | H15: Excel | L15: time_static | M15: substantive procedure — standard
A16: FS-6-2 | D16: FS Section | E16: Financial Statements and Deliverables Section | F16: Final Analytical Procedures - Opinion Unit #3 | G16: HCLLP WP | H16: Excel | L16: time_static | M16: substantive procedure — standard
A17: FS-6-3 | D17: FS Section | E17: Financial Statements and Deliverables Section | F17: Final Analytical Procedures - Opinion Unit #4 | G17: HCLLP WP | H17: Excel | L17: time_static | M17: substantive procedure — standard
A18: FS-7 | D18: FS Section | E18: Financial Statements and Deliverables Section | F18: Estimates Identification and Retrospective Review | G18: =_xlfn.XLOOKUP(F18,'NPO Caseware'!G:G,'NPO Caseware'!H:H) -> PPC | H18: =_xlfn.XLOOKUP(F18,'NPO Caseware'!G:G,'NPO Caseware'!I:I) -> Word | I18: ALG-CX-3.6 | L18: time_static | M18: FS deliverables — default standard procedure (section default)
A19: FS-8 | D19: FS Section | E19: Financial Statements and Deliverables Section | F19: Supervision, Review and Approval Form | G19: =_xlfn.XLOOKUP(F19,'NPO Caseware'!G:G,'NPO Caseware'!H:H) -> PPC | H19: =_xlfn.XLOOKUP(F19,'NPO Caseware'!G:G,'NPO Caseware'!I:I) -> Word | I19: ALG-CX-14 | L19: time_static | M19: supervision/review form — standard
A20: FS-9 | D20: FS Section | E20: Financial Statements and Deliverables Section | F20: Retirment Plan Employee and Employer Contribution Report - Footnote Support | G20: =_xlfn.XLOOKUP(F20,'NPO Caseware'!G:G,'NPO Caseware'!H:H) -> PBC | H20: =_xlfn.XLOOKUP(F20,'NPO Caseware'!G:G,'NPO Caseware'!I:I) -> PDF | L20: time_static | M20: FS deliverables — default standard procedure (section default)
A21: FS-9-1 | D21: FS Section | E21: Financial Statements and Deliverables Section | F21: Additional FS Footnote Support #2 | G21: =_xlfn.XLOOKUP(F21,'NPO Caseware'!G:G,'NPO Caseware'!H:H) -> PBC | H21: =_xlfn.XLOOKUP(F21,'NPO Caseware'!G:G,'NPO Caseware'!I:I) -> PDF | L21: time_static | M21: FS deliverables — default standard procedure (section default)
A22: FS-9-2 | D22: FS Section | E22: Financial Statements and Deliverables Section | F22: Additional FS Footnote Support #3 | G22: =_xlfn.XLOOKUP(F22,'NPO Caseware'!G:G,'NPO Caseware'!H:H) -> PBC | H22: =_xlfn.XLOOKUP(F22,'NPO Caseware'!G:G,'NPO Caseware'!I:I) -> PDF | L22: time_static | M22: FS deliverables — default standard procedure (section default)
A23: FS-10 | D23: FS Section | E23: Financial Statements and Deliverables Section | F23: Component Audited FS (if applicable) | G23: PBC | H23: PDF | L23: time_static | M23: group audit — standard procedure
A24: FS-10-1 | D24: FS Section | E24: Financial Statements and Deliverables Section | F24: Request for Representation from Component Auditor When Reference Will be Made (if applicable) | G24: PPC | H24: Word | I24: ALG-CX-14.1 | L24: time_static | M24: group audit — standard procedure
A25: FS-10-2 | D25: FS Section | E25: Financial Statements and Deliverables Section | F25: Letter of Instructions from Group Auditor to Component Auditors When Reference Will be Made (if applicable) | G25: PPC | H25: Word | I25: ALG-CX-14.3 | L25: time_static | M25: group audit — standard procedure
A26: FS-10-3 | D26: FS Section | E26: Financial Statements and Deliverables Section | F26: Peer Review Report of Component Auditor (if applicable) | G26: PBC | H26: PDF | L26: time_static | M26: group audit — standard procedure
A27: ML-1 | D27: ML Section | E27: Management Advisory Letter and Findings Section | F27: Schedule of Findings and Questioned Costs | G27: =_xlfn.XLOOKUP(F27,'NPO Caseware'!G:G,'NPO Caseware'!H:H) -> HCLLP WP | H27: =_xlfn.XLOOKUP(F27,'NPO Caseware'!G:G,'NPO Caseware'!I:I) -> Caseview | L27: time_static | M27: questioned costs listing — format stable
A28: ML-2 | D28: ML Section | E28: Management Advisory Letter and Findings Section | F28: Corrective Action Plan (Provided by Client) | G28: =_xlfn.XLOOKUP(F28,'NPO Caseware'!G:G,'NPO Caseware'!H:H) -> PBC | H28: =_xlfn.XLOOKUP(F28,'NPO Caseware'!G:G,'NPO Caseware'!I:I) -> Word | L28: time_static | M28: ML/findings — finding structure procedural (section default)
A29: ML-3 | D29: ML Section | E29: Management Advisory Letter and Findings Section | F29: Inventory Tracking Listing of Findings and Questioned Costs - Financial Statement Findings | G29: =_xlfn.XLOOKUP(F29,'NPO Caseware'!G:G,'NPO Caseware'!H:H) -> HCLLP WP | H29: =_xlfn.XLOOKUP(F29,'NPO Caseware'!G:G,'NPO Caseware'!I:I) -> Caseview | L29: time_static | M29: questioned costs listing — format stable
A30: ML-3-1 | D30: ML Section | E30: Management Advisory Letter and Findings Section | F30: Inventory Tracking Listing of Findings and Questioned Costs - Federal Award Findings | G30: =_xlfn.XLOOKUP(F30,'NPO Caseware'!G:G,'NPO Caseware'!H:H) -> HCLLP WP | H30: =_xlfn.XLOOKUP(F30,'NPO Caseware'!G:G,'NPO Caseware'!I:I) -> Caseview | L30: time_static | M30: questioned costs listing — format stable
A31: ML-4 | D31: ML Section | E31: Management Advisory Letter and Findings Section | F31: Control Deficiency Evaluation Worksheet | G31: =_xlfn.XLOOKUP(F31,'NPO Caseware'!G:G,'NPO Caseware'!H:H) -> PPC | H31: =_xlfn.XLOOKUP(F31,'NPO Caseware'!G:G,'NPO Caseware'!I:I) -> Word | I31: ALG-CX-15.1 | L31: time_static | M31: IC evaluation matrix — standard
A32: ML-5 | D32: ML Section | E32: Management Advisory Letter and Findings Section | F32: Noncompliance Evaluation Form - Federal Award Programs | G32: =_xlfn.XLOOKUP(F32,'NPO Caseware'!G:G,'NPO Caseware'!H:H) -> PPC | H32: =_xlfn.XLOOKUP(F32,'NPO Caseware'!G:G,'NPO Caseware'!I:I) -> Word | L32: time_static | M32: ML/findings — finding structure procedural (section default)
A33: ML-6 | D33: ML Section | E33: Management Advisory Letter and Findings Section | F33: Status of Prior Year Findings and Questioned Costs | G33: =_xlfn.XLOOKUP(F33,'NPO Caseware'!G:G,'NPO Caseware'!H:H) -> HCLLP WP | H33: =_xlfn.XLOOKUP(F33,'NPO Caseware'!G:G,'NPO Caseware'!I:I) -> Word | L33: time_static | M33: questioned costs listing — format stable
A34: TB-1 | D34: TB Section | E34: Trial Balance Section | F34: Trial Balance - Opinion Unit #1 [e.g. Governmental Activities] (Automatic CaseWare Document) | G34: HCLLP WP | H34: LeadSheet | L34: time_static | M34: TB — mapping stable 4-5 yrs
A35: TB-1-1 | D35: TB Section | E35: Trial Balance Section | F35: Trial Balance - Opinion Unit #2 (Automatic CaseWare Document) | G35: HCLLP WP | H35: LeadSheet | L35: time_static | M35: TB — mapping stable 4-5 yrs
A36: TB-1-2 | D36: TB Section | E36: Trial Balance Section | F36: Trial Balance - Opinion Unit #3 (Automatic CaseWare Document) | G36: HCLLP WP | H36: LeadSheet | L36: time_static | M36: TB — mapping stable 4-5 yrs
A37: TB-1-3 | D37: TB Section | E37: Trial Balance Section | F37: Trial Balance - Opinion Unit #4 (Automatic CaseWare Document) | G37: HCLLP WP | H37: LeadSheet | L37: time_static | M37: TB — mapping stable 4-5 yrs
A38: TB-2 | D38: TB Section | E38: Trial Balance Section | F38: Trial Balance Import File | G38: HCLLP WP | H38: Excel | L38: time_static | M38: TB — mapping stable 4-5 yrs
A39: TB-3 | D39: TB Section | E39: Trial Balance Section | F39: Adjusting Journal Entries Report (Automatic CaseWare Document) | G39: =_xlfn.XLOOKUP(F39,'NPO Caseware'!G:G,'NPO Caseware'!H:H) -> HCLLP WP | H39: =_xlfn.XLOOKUP(F39,'NPO Caseware'!G:G,'NPO Caseware'!I:I) -> LeadSheet | L39: time_static | M39: AJE/RJE — JE listing format stable
A40: TB-4 | D40: TB Section | E40: Trial Balance Section | F40: Reclassifying Journal Entries Report (Automatic CaseWare Document) | G40: =_xlfn.XLOOKUP(F40,'NPO Caseware'!G:G,'NPO Caseware'!H:H) -> HCLLP WP | H40: =_xlfn.XLOOKUP(F40,'NPO Caseware'!G:G,'NPO Caseware'!I:I) -> LeadSheet | L40: time_static | M40: TB section — format/mapping stable 4-5 yrs (section default)
...

Sheet NPO Caseware
B2: WP Index ID | C2: Process Flow | D2: Process Flow-2 | E2: Type | F2: FS Section | G2: Document Name | H2: Source | I2: File Format | J2: SOP | K2: Mapping | L2: PPC Form Reference | M2: Notes | N2: SOP prepared | O2: Time Bucket | P2: Rationale | Q2: Audit Manager Override | R2: Audit Reviewer Note
B3: FS-FINAL | C3: Reporting | D3: Financial Statement and Deliverables Review | E3: FS Section | F3: Financial Statements and Deliverables Section | G3: Final PDF Copy of the Audited Financial Statements | H3: HCLLP WP | I3: PDF | J3: Needed | O3: time_static | P3: FS draft/final — FS layout stable
B4: FS-CV | C4: Reporting | D4: Financial Statement and Deliverables Review | E4: FS Section | F4: Financial Statements and Deliverables Section | G4: Working Copy of the CaseView Financial Statements | H4: HCLLP WP | I4: PDF | J4: Needed | O4: time_static | P4: CaseView FS working copy — layout stable
B5: FS-CV-1 | C5: Reporting | D5: Financial Statement and Deliverables Review | E5: FS Section | F5: Financial Statements and Deliverables Section | G5: Cash Flow Worksheet (if applicable) | H5: HCLLP WP | I5: Excel | J5: Needed | O5: time_static | P5: cash flow worksheet — format stable
B6: FS-PROG | C6: Reporting | D6: Financial Statement and Deliverables Review | E6: FS Section | F6: Financial Statements and Deliverables Section | G6: Audit Program for General Auditing and Completion Procedures | H6: PPC | I6: Word | J6: Needed | L6: NPO-AP-20 | O6: time_static | P6: audit program — standard procedure
B7: FS-PROG-1 | C7: Reporting | D7: Financial Statement and Deliverables Review | E7: FS Section | F7: Financial Statements and Deliverables Section | G7: Additional General Auditing and Completion Procedures for an Initial Audit | H7: PPC | I7: Word | J7: Needed | L7: NPO-IA-20 | M7: Use only if this is a first year audit for Harshwal & CO/Blue Arrow CPAs | O7: time_static | P7: FS deliverables — default standard procedure (section default)
B8: FS-1 | C8: Final Stage | D8: Financial Statement and Deliverables Review | E8: FS Section | F8: Financial Statements and Deliverables Section | G8: Disclosure Checklist | H8: PPC | I8: Word | J8: Needed | L8: NPO-CX-13 | O8: time_static | P8: disclosure checklist — slowly evolving
B9: FS-2 | C9: Reporting | D9: Management Letters | E9: FS Section | F9: Financial Statements and Deliverables Section | G9: Management Representation Letter (Client Endorsed) | H9: PBC | I9: PDF | J9: NA | O9: time_static | P9: MRL template — standard
B10: FS-2-1 | C10: Reporting | D10: Management Letters | E10: FS Section | F10: Financial Statements and Deliverables Section | G10: Management Representation Letter Template | H10: PPC | I10: Word | J10: Needed | L10: NPO-CL-3.1 | O10: time_static | P10: MRL template — standard
B11: FS-3 | C11: Planning Stage | D11: Information Gathering | E11: FS Section | F11: Financial Statements and Deliverables Section | G11: Legal Representation Letter (Returned Response from Attorney) | H11: HCLLP WP | I11: PDF | J11: Needed | O11: time_static | P11: FS deliverables — default standard procedure (section default)
B12: FS-4 | C12: Final Stage | D12: Exit Conference | E12: FS Section | F12: Financial Statements and Deliverables Section | G12: Communication to Those Charged with Governance at Conclusion (Final PDF Copy provided to Client) | H12: HCLLP WP | I12: PDF | J12: NA | O12: time_static | P12: FS draft/final — FS layout stable
B13: FS-4-1 | C13: Reporting | D13: Exit Conference | E13: FS Section | F13: Financial Statements and Deliverables Section | G13: Communication to Those Charged with Governance at Conclusion Template | H13: PPC | I13: Word | J13: Needed | L13: NPO-CL-5.2 | O13: time_static | P13: TCWG comm — standard
B14: FS-5 | C14: Reporting | D14: Exit Conference | E14: FS Section | F14: Financial Statements and Deliverables Section | G14: Audit Presentation PowerPoint | H14: HCLLP WP | I14: PPT | J14: Needed | O14: time_static | P14: FS deliverables — default standard procedure (section default)
B15: FS-6 | C15: Evidence Evaluation | D15: Analytics | E15: FS Section | F15: Financial Statements and Deliverables Section | G15: Final Analytical Procedures | H15: HCLLP WP | I15: Excel | J15: Needed | O15: time_static | P15: substantive procedure — standard
B16: FS-7 | C16: Reporting | D16: Management Letters | E16: FS Section | F16: Financial Statements and Deliverables Section | G16: Estimates Identification and Retrospective Review | H16: PPC | I16: Word | J16: Needed | L16: NPO-CX-3.6 | O16: time_static | P16: FS deliverables — default standard procedure (section default)
B17: FS-8 | C17: Reporting | D17: Financial Statement and Deliverables Review | E17: FS Section | F17: Financial Statements and Deliverables Section | G17: Supervision, Review and Approval Form | H17: PPC | I17: Word | J17: Needed | L17: NPO-CX-14 | O17: time_static | P17: supervision/review form — standard
B18: FS-9 | C18: Evidence Evaluation | D18: Analytics | E18: FS Section | F18: Financial Statements and Deliverables Section | G18: Retirment Plan Employee and Employer Contribution Report - Footnote Support | H18: PBC | I18: PDF | J18: NA | O18: time_static | P18: FS deliverables — default standard procedure (section default)
B19: FS-9-1 | C19: Reporting | D19: Financial Statement Review | E19: FS Section | F19: Financial Statements and Deliverables Section | G19: Additional FS Footnote Support #2 | H19: PBC | I19: PDF | J19: NA | O19: time_static | P19: FS deliverables — default standard procedure (section default)
B20: FS-9-2 | C20: Reporting | D20: Financial Statement Review | E20: FS Section | F20: Financial Statements and Deliverables Section | G20: Additional FS Footnote Support #3 | H20: PBC | I20: PDF | J20: NA | O20: time_static | P20: FS deliverables — default standard procedure (section default)
B21: ML-1 | C21: Final Stage | D21: Exit Conference | E21: ML Section | F21: Management Advisory Letter and Findings Section | G21: Schedule of Findings and Questioned Costs | H21: HCLLP WP | I21: Caseview | J21: Needed | O21: time_static | P21: questioned costs listing — format stable
B22: ML-2 | C22: Final Stage | D22: Exit Conference | E22: ML Section | F22: Management Advisory Letter and Findings Section | G22: Corrective Action Plan (Provided by Client) | H22: PBC | I22: Word | J22: NA | O22: time_static | P22: ML/findings — finding structure procedural (section default)
B23: ML-3 | C23: Final Stage | D23: Exit Conference | E23: ML Section | F23: Management Advisory Letter and Findings Section | G23: Inventory Tracking Listing of Findings and Questioned Costs - Financial Statement Findings | H23: HCLLP WP | I23: Caseview | J23: Needed | O23: time_static | P23: questioned costs listing — format stable
B24: ML-3-1 | C24: Final Stage | D24: Exit Conference | E24: ML Section | F24: Management Advisory Letter and Findings Section | G24: Inventory Tracking Listing of Findings and Questioned Costs - Federal Award Findings | H24: HCLLP WP | I24: Caseview | J24: Needed | O24: time_static | P24: questioned costs listing — format stable
B25: ML-4 | C25: Reporting | D25: Audit Findings | E25: ML Section | F25: Management Advisory Letter and Findings Section | G25: Control Deficiency Evaluation Worksheet | H25: PPC | I25: Word | J25: Needed | L25: NPO-CX-15.1 | O25: time_static | P25: IC evaluation matrix — standard
B26: ML-5 | E26: ML Section | F26: Management Advisory Letter and Findings Section | G26: Noncompliance Evaluation Form - Federal Award Programs | H26: PPC | I26: Word | J26: Needed | L26: NPO-CX-12.3 | O26: time_static | P26: ML/findings — finding structure procedural (section default)
B27: ML-6 | C27: Pre- Engagement Phase | D27: Risk Assessment | E27: ML Section | F27: Management Advisory Letter and Findings Section | G27: Status of Prior Year Findings and Questioned Costs | H27: HCLLP WP | I27: Word | J27: Needed | O27: time_static | P27: questioned costs listing — format stable
B28: TB-1 | C28: Planning Stage | D28: Information Gathering | E28: TB Section | F28: Trial Balance Section | G28: Trial Balance - Final (Automatic CaseWare Document) | H28: HCLLP WP | I28: Caseview | J28: NA | O28: time_static | P28: TB — mapping stable 4-5 yrs
B29: TB-2 | C29: Planning Stage | D29: Information Gathering | E29: TB Section | F29: Trial Balance Section | G29: Trial Balance Import File (client provided and formatted for import) | H29: HCLLP WP | I29: Excel | J29: Needed | O29: time_static | P29: TB — mapping stable 4-5 yrs
B30: TB-3 | C30: Detailed Audit Procedures | D30: Testing procedures | E30: TB Section | F30: Trial Balance Section | G30: Adjusting Journal Entries Report (Automatic CaseWare Document) | H30: HCLLP WP | I30: LeadSheet | J30: NA | O30: time_static | P30: AJE/RJE — JE listing format stable
B31: TB-4 | C31: Detailed Audit Procedures | D31: Testing procedures | E31: TB Section | F31: Trial Balance Section | G31: Reclassifying Journal Entries Report (Automatic CaseWare Document) | H31: HCLLP WP | I31: LeadSheet | J31: NA | O31: time_static | P31: TB section — format/mapping stable 4-5 yrs (section default)
B32: TB-5 | C32: Detailed Audit Procedures | D32: Testing procedures | E32: TB Section | F32: Trial Balance Section | G32: Passed Adjusting Journal Entries Report (Automatic CaseWare Document) | H32: HCLLP WP | I32: LeadSheet | J32: NA | O32: time_static | P32: AJE/RJE — JE listing format stable
B33: TB-6 | C33: Reporting | D33: Audit Findings | E33: TB Section | F33: Trial Balance Section | G33: Audit Difference Evaluation Form | H33: PPC | I33: Word | J33: Needed | L33: NPO-CX-12.2 | O33: time_static | P33: audit difference eval — format stable
B34: PL-PROG | C34: Planning Stage | D34: Completion (Planning Stage) | E34: PL Section | F34: Planning Section | G34: Audit Program for General Planning Procedures | H34: PPC | I34: Word | J34: Needed | L34: NPO-AP-10 | O34: time_static | P34: audit program — standard procedure
A35: OK | B35: PL-1 | C35: Pre- Engagement Phase | D35: Engagement Independence Evaluation | E35: PL Section | F35: Planning Section | G35: Engagement Acceptance and Continuation Form | H35: PPC | I35: Word | J35: Needed | L35: NPO-CX-1.1 | O35: time_static | P35: engagement procedure — standard
B36: PL-2 | C36: Pre- Engagement Phase | D36: Engagement Independence Evaluation | E36: PL Section | F36: Planning Section | G36: Evaluating Independence - Yellowbook and GAAS Audits | H36: PPC | I36: Word | J36: Needed | L36: NPO-CX-1.3 | O36: time_static | P36: independence checklist — standard procedure
B37: PL-3 | C37: Pre- Engagement Phase | D37: Engagement Independence Evaluation | E37: PL Section | F37: Planning Section | G37: Continuing Professional Education Documentation Form | H37: PPC | I37: Word | J37: Needed | L37: NPO-CX-1.4 | O37: time_static | P37: Planning — standard procedure by default (section default)
A38: OK | B38: PL-4 | C38: Pre- Engagement Phase | D38: Engagement letter | E38: PL Section | F38: Planning Section | G38: Engagement Letter (Client endorsed) | H38: HCLLP WP | I38: PDF | J38: NA | O38: time_static | P38: engagement procedure — standard
A39: OK | B39: PL-4-1 | C39: Pre- Engagement Phase | D39: Engagement letter | E39: PL Section | F39: Planning Section | G39: Engagement Letter template | H39: HCLLP WP | I39: Caseview | J39: Needed | O39: time_static | P39: engagement procedure — standard
B40: PL-5 | C40: Planning Stage | D40: Client Communication (Planning Stage) | E40: PL Section | F40: Planning Section | G40: Communication to Those Charged with Governance During Planning | H40: PPC | I40: Word | J40: Needed | L40: NPO-CX-5.1 | O40: time_static | P40: TCWG comm — standard
B41: PL-6 | C41: Planning Stage | D41: Information Gathering | E41: PL Section | F41: Planning Section | G41: Understanding the Entity and Identifying Risks | H41: PPC | I41: Word | J41: Needed | L41: NPO-CX-3.1 | O41: time_static | P41: understanding entity — standard
...

Sheet Process Flow 1
A2: 1 | B2: Pre- Engagement Phase
B4: Client Evaluation and Acceptance | D4: Engagement letter | F4: Engagement Independence Evaluation | H4: Client Communication (Pre-Engagement Phase) | L4: Tools:
L5: PPC Checkpoint
B6: Identify potential client | D6: Select the appropriate EL template based on entity type. | F6: Assess firm personnel resources and determine engagement team. | H6: Conduct Client Kick-off Meeting via Zoom or at the client’s location. | L6: EL Bot
B7: Conduct internal discussions to determine engagement feasibility. | D7: Customize the letter via Caseview or EL bot | F7: Perform an independence check of engagement team before starting the audit. Done via checklist | H7: Introduce the Audit Team to the client. | L7: Monday.com
B8: Gather preliminary client information, including key risk factors such as cash flow issues, pending law suits. | D8: Define audit scope, responsibilities, and reporting framework. | F8: Document findings and approvals using the Engagement Independence Compliance form. | H8: Review Prior Year (PY) Report for reference. | L8: Suralink (E-signature)
B9: Evaluate the client’s background, industry, and risk profile. | D9: Confirm management’s responsibility for financial statements | F9: Review client relationships and past services to identify potential threats to independence. | H9: Discuss Audit Plan & Timeline with client. | L9: Suralink
B10: Assess independence, potential conflicts, and compliance requirements. (Firm-wide analysis) | D10: Confirm audit timelines, deliverables, and communication protocols. | F10: Assess nonattest services and evaluate their impact on independence. | H10: Discuss audit deliverables and expectations
B11: Prepare engagement proposal including cost determination | D11: Share the EL draft with the review team and obtain Engagement Partner approval EL for issuance to client. | F11: Obtain Engagement Partner approval for engagement team independence evaluation. | H11: Document the meeting in the Entrance Conference Memo.
B12: Obtain Engagement Partner approval for proposal | D12: Upon Engagement Partner approval send EL to the client via email or Suralink e-signature. | H12: Complete PBC List | R12: S
B13: Submit proposal to potential client. | D13: Receive the signed EL from client management and document and place into Caseware Engagement file. | H13: Obtain Engagement Partner approval for PBC list
H14: Upload PBC list to Suralink and email to client
A20: 2 | B20: Planning Stage
B22: Information Gathering | D22: Client Questionnaires | F22: Internal Control and Risk Assessment | H22: Client Communication (Planning Stage) | J22: Sample Planning and Selection | L22: Completion (Planning) | O22: Tools:
O23: Suralink
B24: Collect necessary documents from the client for audit planning. | D24: Distribute and collect Fraud risk and Related Party Questionnaires from the client. | F24: Document entity level controls | H24: Prepare Communications Letter to Those Charged with Governance During Planning form. (Required Communications) | J24: Determine areas for which sampling for substantive testing is required. | L24: Complete Planning Program | O24: PPC Smart practice Aids
B25: Obtain attorney details contact details, prepare, and send legal confirmation requests; review and document responses. | D25: Assess fraud risks based on questionnaire responses. | F25: Document internal control processes for financial reporting, IT controls, and transaction processing. | H25: Obtain Engagement Partner approval of Planning Communications Letter. | J25: Determine populations for samples. | O25: Internal Questionnaires
B26: Obtain listing of Board/Governance Members and contact information | D26: Identify and evaluate related party transactions for potential conflicts or undisclosed relationships. | F26: Prepare Internal Control Memos and identify key internal controls over significant audit areas such as Disbursements, Payroll, Revenue, and Financial Close. | H26: Send planning communications letter to Goveranance and Management | J26: Plan samples sizes | O26: Confirmation.com
B27: Obtain listing of Management and Key Accounting Staff and contact information | D27: Cross-check responses with financial records and transaction details. | F27: Conduct internal control walkthroughs of key internal controls over the significant transaction cycles. | H27: Prepare confirmation letters to be sent to external parties (attorneys, accounts receivable, depository accounts, investment accounts, etc) | J27: Select samples
B28: Board Minutes - Review and analyze board meeting minutes to capture significant financial and operational decisions and events | D28: Assess and document litigation and contingent liabilities for financial and compliance impact. | F28: Complete Understanding and Evaluating the System of Internal Control form | H28: Provide confirmation letters to client for signature/authorization. | J28: Obtain Engagement Partner approval for sampling methodology and samples selected.
B29: Trial Balance Import - Import and map trial balance(s) received from client. | D29: Document findings and incorporate them into the overall risk assessment. | F29: Determine materiality thresholds by completing the Preliminary Materiality Worksheet. | H29: Prepare Confirmation Control Log documenting dates sent and received from external parties | J29: Send samples to client via email and upload to SURALINK.
B30: Current Year Payment Register - obtain and summarize FY 2025 check register by vendor. Select sample of significant and/or unusual vendors for fraud risk and related party testing. | F30: Perform a Preliminary Analytical Review to identify unusual trends and variances to assist with Risk Assessment and determining the nature, timing and extent of audit procedures to be performed. | H30: Receive confirmation letters back from client.
B31: Trial Balance Import - Import and map trial balance(s) received from client. | F31: Complete Inherent Risk Assessment (IR) through inherent risk assessment forms and fraud inquiries. | H31: Send confirmation letters to external parties.
B32: Complete Understanding the Entity and Identifying Risks form | F32: Determine if internal controls will be tested to support a planned level of control risk less than HIGH.
F33: Complete overall Risk Assessment (RMM) and complete Risk Assessment Summary Form.
F34: Obtain Engagement Partner approval for Risk Assessment.
F35: Prepare audit programs based on overall Risk Assessment
F36: Hold an engagement team discussion with team and ensure Engagement Partner is present.
A41: 3 | B41: Detailed Audit Procedures
B43: Documentation review | D43: Testing procedures | L43: Tools:
L44: CaseWare
L45: PPC templates
B46: Gather and examine financial documents (invoices, receipts, contracts, agreements) for audit assertions like completeness and relevance. | D46: Prepare testwork (TW) files for key financial areas, including revenue, disbursements, payroll, and journal entries.
B47: Verify approvals and authorization for disbursements, payroll, and significant transactions. | D47: Assess internal controls by testing approvals, classifications, and compliance with policies.
B48: Identify missing or inconsistent documentation and request clarifications from the client. | D48: Perform substantive testing by selecting samples and verifying recorded transactions.
B49: Cross check with external confirmations (bank statements, AR and AP confirmation, legal contracts) to validate accuracy. | D49: Analyze trends and variances to detect potential misstatements.
B50: Maintain organized and well referenced audit documentation to support conclusions
A55: 4 | B55: Fieldwork
B57: Team Collaboration | D57: Evidence Collection | F57: Tools:
F58: CaseWare
...

Sheet Automated Process Flow 2
A2: 1 | B2: Pre- Engagement Phase
B4: Automated Client Onboarding | D4: Automated Engagement letters | F4: Automated Risk Assessment | H4: Automation Tools:
H5: PPC Checkpoint- Auto-generates letters
B6: Client details are auto-populated in Monday.com from previous engagements. | D6: EL is generated in CaseView, using predefined templates. | F6: PPC Smart Practice Aids assist with risk assessment | H6: EL Bot- RFP based letter generation
B7: System auto-validates client name, contact, industry, and prior audit history. | D7: The generated EL is reviewed for accuracy before sharing. | F7: Engagement details are selected, and client data auto-fills in PPC Smart Practice Aids. | H7: Monday.com- Automated task tracking
B8: New clients are manually added to CaseWare and Monday.com's database | D8: Share with Onshore audit team and then with the client via DocuSign. | F8: Risk assessment questions are answered, and risks are categorized automatically.
F9: Audit procedures are suggested based on identified risks.
F10: Auto-filled audit program workpapers are generated and linked to CaseWare.
A16: 2 | B16: Planning Stage
B18: Automated Document Collection | D18: AI-Driven Data Analysis | F18: Automated Risk Assessment | H18: Automation Tools:
H19: Suralink- Auto-tracks documents
B20: Documents are requested via the Suralink Portal using the audit prep guide, following the CaseWare folder structure. | D20: Prior-year trial balance (PY TB) is already stored in CaseWare. | F20: A digital questionnaire is shared with the client to collect risk-related information. | H20: PPC Smart Practices Aids
B21: Other pending client documents are requested via Outlook | D21: When the current year trial balance is imported, the preliminary analytical lead sheet auto-generates. | F21: Clients complete and submit the questionnaire, providing details on financial processes, internal controls, and compliance risks. | H21: Automated Risk Assessment
D22: The lead sheet auto-populates prior-year figures, variance amounts, and variance percentages. | F22: Auditors review the completed questionnaire and incorporate identified risks into the audit planning process. | H22: Digital Questionnaires
D23: Unusual fluctuations are identified for further review based on variance analysis.
A29: 3 | B29: Execution Phase
B31: Automated Document Extraction | D31: Automated Reconciliations | F31: Automated testing | H31: Automation Tools:
H32: CaseWare- Auto-calculations
B33: 1. Client-Provided Documents (via Suralink): | D33: Preliminary analytics auto-generate in CaseWare upon trial balance import, using last year’s audited trial balance for comparison | F33: PPC Templates auto-generate sampling selections based on risk criteria. | H33: PPC Templates- Automated Sampling
B34: Client uploads documents to the Suralink PBC list, assigned to specific line items. | F34: CaseWare auto-validates trial balance data for completeness. | H34: Auto Linking to Trial Balance
B35: Suralink highlights new uploads daily for easy tracking. | F35: Duplicate transactions and unusual patterns are flagged for review.
B36: The audit staff reviews, downloads, and organizes files within the appropriate CaseWare document manager folder.
B37: 2. PPC Documents (via PPC Templates & CaseWare)
B38: The required PPC templates and audit programs are extracted directly from the PPC tool during the audit process.
A46: 4 | B46: Evidence Management
B48: Automated Evidence Collection | D48: Automated Documentation | F48: Auto-referencing | H48: Automation Tools:
H49: Suralink-Auto-tracking
B50: Pending item list is imported into Suralink, including audit requests and selected transactions for testing. | D50: Suralink documents are uploaded into CaseWare, mapping to relevant audit workpapers. | F50: CaseWare assigns an automatic file number when a file is added. | H50: CaseWare- Auto-referencing
B51: Client uploads supporting documents for selected items in the assigned audit sections. | D51: Audit workpapers can be dragged from the PPC audit library into CaseWare. | F51: Excel files use formulas to auto-reference the file name as the testwork name. | H51: Automated Evidence tagging
B52: Auditors review uploaded documents and request additional information if necessary. | D52: Testwork files can be copied from other peer client CaseWare files. | F52: PDF files require manual referencing by creating reference boxes.
B53: Status tracking in Suralink helps monitor pending and completed requests. | D53: Documents received via Outlook can be manually dragged into CaseWare. | F53: PPC Word files come with built-in automatic referencing.
B54: Audit confirmations are initiated and tracked through Confirmation.com, streamlining bank, legal, and third-party confirmations. | D54: Confirmations from Confirmation.com can be imported into CaseWare. | F54: Lead sheet references are automatically generated in CaseWare.
D55: Signed documents from DocuSign can be manually added to CaseWare.
A60: 5 | B60: Review Process
B62: Automated Analytics | D62: Auto-generated insights | F62: Automated issue tracking | H62: Automation Tools:
H63: CaseWare- Auto-analytics
B64: Preliminary analytics auto-generate in CaseWare upon trial balance import, using last year’s audited trial balance for comparison. | D64: CaseView auto-populates financial statements and MD&A using imported trial balance data. | F64: Reviewers can add comments on each testwork file, tagging team members for follow-ups. | H64: Automated exception reporting
B65: Revenue, expense, and payroll analytics auto-populate similarly, leveraging prior year data. | D65: CaseView automatically matches financial statements and flags errors if the balance sheet does not tie. | F65: Outstanding review notes are tracked | H65: Real-time dashboard updates
D66: MD&A statements is auto linked with financial statements
D67: Notes to financial statements auto-reconcile with financial data
...

Sheet Flow
B1: Prepare | Plan | Audit | Report | Close
B2: AiM: Flowchart | 7Mar26
B3: Phases | D3: Prepare | G3: Plan | M3: Audit | R3: Report | V3: Close
B4: Knowledge / context (documents and files) | D4: EL templates, HCLLP WP and PBC | E4: PPC, PBC and HCLLP WP | F4: PBC, HCLLP WP, PPC documents and templates | G4: PY TB, TB, HCLLP WP | H4: PY TB, TB, HCLLP WP | I4: PPC, PBC, HCLLP WP and Questionnaires | J4: PPC templates, risk criteria | L4: HCLLP WP, TW, Confirmations and signed documents | M4: PPC and Testwork files | N4: HCLLP WP, TP, PY TB and TB | O4: HCLLP WP, TW, FS, MD&A, Notes to financial statements | P4: Testwork file, Engagement team roles | Q4: PPC audit report templates | S4: PPC Checklist templates (Word) and lead sheet | T4: EL, management letters and audit reports | U4: CaseWare files | V4: Closing memos, summary and PPT | Y4: TB and PY TB
B5: Systems / databases and tools | C5: CaseWare and Monday.com | D5: CaseView, DocuSign and EL Generator | E5: PPC Checkpoint letter generator | F5: Doclink / Suralink, Outlook, CaseWare and PPC tool | G5: CaseWare | H5: CaseWare and TB auto-linking | J5: CaseWare | K5: CaseWare, Doclink / Suralink, Confirmation.com, auto-evidence tagging | L5: CaseWare, Doclink / Suralink, Confirmation.com and DocuSign | M5: CaseWare, Excel, Word, PDF and auto-referencing | N5: CaseWare, GenAI analytics and auto exception reporting | O5: CaseWare and Tie-out | P5: CaseWare | Q5: CaseWare, CaseView and GenAI reporter | R5: CaseWare and CaseView | S5: CaseWare, CaseView, Checklist and auto disclosure checker | T5: DocuSign, Doclink / Suralink and Outlook | U5: CaseWare | V5: Auto-generate summary, auto generate memos and PPT | X5: Auto scheduled follow-ups | Y5: CaseWare, auto recommendations tracker and GenAI insights
B6: AI jobs / agents (Agentic AI system through orchestration via MCP server protocol with multi-LLM complexion model) | C6: On-board client for new engagement: - Reference previous engagements in CaseWare - Validate client name, contact, industry and prior audit history - Populate Monday.com with the client and new engagement information - Update CaseWare accordingly | D6: Generate EL: - Get client and engagement details from CaseWare and Monday.com - Use predefined templates - Generate EL in CaseView | E6: Assess risks: - Select engagement details - Use client data to fill-in PPC Smart Practice Aids - Answer risk assessment questions - Categorize risks - Suggest audit procedure based on identified risks - Generate WPs and link to CaseWare | F6: Collect documents: - Follow CaseWare folder structure - Setup PBC list in Doclink/Suralink - Use audit prep guide - Request documents via secured document sharing system (Doclink or Suralink) - Request other documents via email (Outlook) - Doclink/Suralink highlights new uploads daily for easy tracking - Organize updated client and engagement documents in CaseWare folder structure - Extract required PPC templates and audit programs from PPC tool | G6: Analyze data: - Reference prior year trail balance (PY TB) already stored in CaseWare - Import current year trial balance (TB) from CaseWare documents - Generate preliminary analytical lead sheet - Populate lead sheet with prior-year figures, variance amounts and variance percentages - Analyze variances / flux analysis - Identify / flag unusual fluctuations | H6: Reconcile (auto-linking to TB): - Generate preliminary analytics in CaseWare from imported trial balance using last year's audited trail balance for comparison | I6: Assess risks: - Share questionnaire with the client to collect risk-related information - Use client provided details from questionnaire on financial processes, internal controls and compliance risks - Identify risks | J6: Test: - Generate sampling selections using PPC templates based on risk criteria - Validate trail balance data for completeness using auto-calculations in CaseWare - Flag duplicate transactions - Flag unusual patterns | K6: Collect and tag evidence: - Import pending items list into Doclink / Suralink - Import audit requests into Doclink / Suralink - Import selected transactions into Doclink / Suralink - Use PBC list updates to carry out testing - Initiate audit confirmations - Track in Confirmation.com streamlining bank, legal and third-party confirmations | L6: Collect documents: - Map Doclink / Suralink documents uploaded into CaseWare to relevant audit workpapers - Drop audit workpapers (WP) from PPC audit library into CaseWare - Copy Testwork (TW) from peer clients in CaseWare - Import confirmations from Confirmaations.com into CaseWare - Add signed documents from DocuSign to CaseWare | M6: Reference: - Assign file number in CaseWare - Use formulas in Excel to auto-reference file name as Testwork (TW) name - Reference PPC Word files - Reference PDF files - Generate references in lead sheet in CaseWare | N6: Generate analytics: - Generate analytics in CaseWare to compare imported trial balance (TB) with previous year's audited trial year (PY TB) - Generate analytics in CaseWare to compare with PY revenue, expense and payroll | O6: Generate insights: - Populate in CaseWare financial statements and management discussions and analysis (MD&A) sections using imported trial balance (TB) data - Flag errors in CaseView for mismatches between financial statements and balance sheet if they do not tie - Link MD&A statements with financial statements - Reconcile Notes to financial statements with financial data | P6: Track issues: - Insert comments on each Testwork (TW) file tagging team members for follow-ups | Q6: Generate report: - Financial Statements (FS): = Import client TB into CaseWare = Populate FS amounts = Generate FS in CaseView - Notes to financial statements (FS): = Update Notes to FS numbers in CaseView - Audit reports: = Select and extract appropriate PPC audit report template in CaseView = Apply firm-wide formatting style, footnotes and headers for consistency | R6: Update financials: - Link all numeric cells in CaseView to adjusted trial balance (ATB) - Update adjustments - Link prior-year amounts to prior-year trial balance (PY TB) as beginning balance - Update client name cells and year related fields in CaseView according to the engagement settings - Check all calculations are formula driven to ensure accuracy and avoid manual errors - Update financial statements real-time in CaseView for across the board consistency | S6: Compliance checks: - Use PPC checklist templates - Check disclosures - Update financial real-time - Auto-generate report in CaseView - Reconcile lead sheet and trail balance mapping to confirm reporting accuracy | T6: E-sign: - Send engagement letters (ELs), management letters and audit reports for e-signature via DocuSign or Doclink / Suralink or Outlook | U6: Archive: - Roll-forward CaseWare for next audit cycle - Remove unnecessary data from prior years (sanitize) - Lock finalized CaseWare files, restricting edits - Retain view-only access to existing users for reference | V6: Summarize: - Generate summary automatically - Compile audit points into PPT | W6: Follow-up: - Flag outstanding PBC (provided by client) requests - Prompt follow-up emails via Doclink / Suralink button | X6: Schedule reviews: - Set review timelines - Track review timelines - Monitor sign-offs | Y6: Predictive analytics: - Generate lead sheet based on prior-year trial balance (PY TB) and current data - Calculate in CaseWare current versus prior-year financials variances for comparison - Identify unseal trends and potential risks from comparisons
B7: Human intervention (Workspace with real-time dashboard updates) | C7: - Manually add new clients to CaseWare and Monday.com database - Partner approves acceptance of new or continuance, including independence before audit begins | D7: - Review EL for accuracy Send to client via DocuSign | E7: - Partner / Sr. Manager approves final materiality, significant risks and audit strategy | F7: - Client provides documents via secured document sharing system (uploads documents to Doclink / Suralink PBC list, assigned to specific line items | G7: - Review unusual fluctuations identified / flagged based on variance analysis | I7: - Client submits completed the questionnaire - Review completed questionnaire - Review identified risks | J7: - Review duplicate transactions identified - Review unusual patterns identified | K7: - Client provides documents via secured document sharing system (uploads documents to Doclink / Suralink PBC list, assigned to specific line items | O7: Handle exception reports using real-time dashboard updates | P7: - Track outstanding review notes | Q7: - Review and update significant accounting policies, contingent libraries and key disclosures | S7: - Ensure reporting requirements are met - Approve before finalization by using sign-off functionality in CaseWare | X7: - Conduct reviews as scheduled | Y7: - Review real-time dashboard updates and alerts
